Workbook
Name AVON: #REF!
Name AVON: #REF!
Name AVON: #REF!
Name AVON: #REF!
Name AVON: #REF!
Name AVON: #REF!
Name AVON: #REF!
Name BEDS: #REF!
Name BEDS: #REF!
Name BEDS: #REF!
Name BEDS: #REF!
Name BEDS: #REF!
Name BEDS: #REF!
Name BEDS: #REF!
Name BEDS1: #REF!
Name BEDS1: #REF!
Name BEDS1: #REF!
Name BERKS: #REF!
Name BERKS: #REF!
Name BERKS: #REF!
Name BERKS: #REF!
Name BERKS: #REF!
Name BERKS: #REF!
Name BERKS: #REF!
Name BUCKS: #REF!
Name BUCKS: #REF!
Name BUCKS: #REF!
Name BUCKS: #REF!
Name BUCKS: #REF!
Name BUCKS: #REF!
Name BUCKS: #REF!
Name CAMBS: #REF!
Name CAMBS: #REF!
Name CAMBS: #REF!
Name CAMBS: #REF!
Name CAMBS: #REF!
Name CAMBS: #REF!
Name CAMBS: #REF!
Name CHESHIRE: #REF!
Name CHESHIRE: #REF!
Name CHESHIRE: #REF!
Name CHESHIRE: #REF!
Name CHESHIRE: #REF!
Name CHESHIRE: #REF!
Name CHESHIRE: #REF!
Name CLEVELAND: #REF!
Name CLEVELAND: #REF!
Name CLEVELAND: #REF!
Name CLEVELAND: #REF!
Name CLEVELAND: #REF!
Name CLEVELAND: #REF!
Name CLEVELAND: #REF!
Name CLWYD: #REF!
Name CLWYD: #REF!
Name CLWYD: #REF!
Name CLWYD: #REF!
Name CLWYD: #REF!
Name CLWYD: #REF!
Name CLWYD: #REF!
Name components_by_LA: #REF!

Sheet Introduction
A8: Mental Health Act Statistics, Annual Figures 2021-22
A9: Data tables
A10: Publication Date: 26 October 2022
A11: Link to publication: http://digital.nhs.uk/pubs/mha2022
A12: Introduction
A13: These tables provide aggregated statistical information on uses of the Mental Health Act ('the Act') in England for patients formally detained in hospitals and patients subject to Community Treatment Orders (CTOs). They provide time series data and breakdowns by type of organisation (NHS and independent sector) and data relating to the legal status of people detained under the Act.
A14: The data sources for each measure are noted at the top of each column of data. In 2016-17, the data were sourced from the Mental Health Services Data Set for the first time (data on uses of the Act in acute settings were collected via the MHA Acute collection in 2016-17 and 2017-18, and then from the Emergencey Care Data Set (ECDS) from 2019-20 onwards). Prior to this, data was sourced from the KP90 aggregate data collection. Due to coverage issues, counts of events and people produced from these new data sources are incomplete and should not be compared to data from the KP90 collection. Please refer to the notes above each table. Users should also consult the Background Data Quality Report for further information on these issues.
A15: Data confidentiality
A16: MHSDS Sub-national figures between 0 and 4 are suppressed and all numbers are rounded to the nearest 5. ECDS sub-national figures between 1 and 7 are suppressed, zeros are shown and all other numbers are rounded to the nearest 5. National figures from both sources are unrounded and unsuppressed.
A18: Contents
A19: Table | B19: Title
A20: Table 1a | B20: ='Table 1a'!A3 -> Detentions under the Mental Health Act 1983, by legal status and provider type, 2013-14 to 2021-22
A21: Table 1b | B21: ='Table 1b'!A3 -> Detentions under the Mental Health Act 1983, by age group and gender, 2021-22
A22: Table 1c | B22: ='Table 1c'!A3 -> Detentions under the Mental Health Act 1983, by ethnicity, 2021-22
A23: Table 1d | B23: ='Table 1d'!A3 -> Detentions under the Mental Health Act 1983, by Sustainability and Transformation Partnership (STP) area, 2021-22
A24: Table 1e | B24: ='Table 1e'!A3 -> Counts and rates of Detention under the Mental Health Act 1983, cross-tabulated by age group, ethnicity and gender, 2021-22
A25: Table 1f | B25: ='Table 1f'!A3 -> Detentions under the Mental Health Act 1983, by Clinical Commissioning Group (CCG) area, 2021-22
A26: Table 1g | B26: ='Table 1g'!A3 -> Detentions under the Mental Health Act 1983, by IMD decile, 2021-22
A27: Table 1h | B27: ='Table 1h'!A3 -> Detentions under the Mental Health Act 1983, by IMD decile and ethnicity, 2021-22
A28: Table 1i | B28: ='Table 1i'!A3 -> Detentions under the Mental Health Act 1983, by Sustainability and Transformation Partnership (STP) area by age group and gender, 2021-22
A29: Table 1j | B29: ='Table 1j'!A3 -> Detentions under the Mental Health Act 1983, by Sustainability and Transformation Partnership (STP) area by ethnicity and deprivation decile, 2021-22
A30: Table 2a | B30: ='Table 2a'!A3 -> Uses of Short Term Orders under the Mental Health Act 1983 by provider type, 2013-14 to 2021-22
A31: Table 2b | B31: ='Table 2b'!A3 -> Uses of Short Term Detention Orders (Place of Safety Orders: Section 136) under the Mental Health Act 1983 by age group and gender, 2021-22
A32: Table 2c | B32: ='Table 2c'!A3 -> Uses of Short Term Detention Orders (Place of Safety Orders: Section 136) under the Mental Health Act 1983 by ethnicity 2021-22
A33: Table 3a | B33: ='Table 3a'!A3 -> Uses of Community Treatment Orders (CTOs) by provider type, 2013-14 to 2021-22
A34: Table 3b | B34: ='Table 3b'!A3 -> Uses of Community Treatment Orders (CTOs) by age group and gender, 2021-22
A35: Table 3c | B35: ='Table 3c'!A3 -> Uses of Community Treatment Orders (CTOs) by ethnicity, 2021-22
A36: Table 4 | B36: ='Table 4'!A3 -> Uses of Sections 2 and 3 of the Mental Health Act 1983 by provider type, 2013-14 to 2021-22
A37: Table 5 | B37: ='Table 5'!A3 -> People subject to the Mental Health Act 1983 on 31st March, by provider, 2015 to 2021
A38: Table 6 | B38: ='Table 6'!A3 -> People subject to repeated detention under the Mental Health Act 1983, by age group, gender and ethnicity, 2021-22
A39: Table 7a | B39: ='Table 7a'!A3 -> Discharges from hospital when previously detained under the Mental Health Act 1983, by age group and gender, 2021-22
A40: Table 7b | B40: ='Table 7b'!A3 -> Discharges from hospital when previously detained under the Mental Health Act 1983, by ethnicity, 2021-22
A41: Table 8a | B41: Length of Detention of patients discharged from hospital when previously detained under the Mental Health Act 1983, by section, age group, gender, ethnicity and deprivation decile, 2021-22, excluding CTOs
A42: Table 8b | B42: Length of Detention of patients discharged from hospital when previously detained under the Mental Health Act 1983, by section, age group, gender, ethnicity and deprivation decile, 2021-22, including CTOs
A43: Table 8c | B43: Number of separate episodes as part of continuous MHA spell
A44: Appendix 1 | B44: Severity of Detention
A46: Further Information
A47: Author: Community and Mental Health Analysis Team, NHS Digital
A48: Responsible Statistician: Giles Foster
A50: Public Enquiries: 0300 303 5678
...

Sheet Table 1a
A1: Table 1a
A3: Detentions under the Mental Health Act 1983, by legal status and provider type, 2013-14 to 2021-22
A5: This table shows the number of detentions starting in the year, including both civil detentions under Part II and detentions via the Criminal Justice System under Part III of the Act. From 2016-17, data is not comparable to previous years due to the change in data source from the KP90 collection to the MHSDS. For further details please refer to the Background Data Quality Report. Detentions are broken down into those occurring on admission and those that followed admission to hospital. The total also includes detentions following use of a Place of Safety order or after the revocation of a Community Treatment Order (CTO). The count of detentions does not include uses of Sections 4, 5(2) & 5(4) or 135 & 136, which are presented in Table 2 as Uses of Short Term Orders. A short term order may be followed by a detention under Sections 2 or 3, and these detentions are shown under the heading ‘Detentions following admission to hospital’ and ‘Detentions following use of Place of Safety Order’. Data for NHS Providers and Independent Sector Providers only includes data from MHSDS for 2021-22. This is due to small numbers in the ECDS data so these have not been included in these counts to prevent disclosure of small numbers. Further details of analytical methods can be found in the metadata file.
B7: All Providers | L7: NHS Providers | V7: Independent Sector Providers
B8: 2013-14 | C8: 2014-15 | D8: 2015-16 | E8: 2016-17 | F8: 2017-18 | G8: 2018-19 | H8: 2019-20 | I8: 2020-21 | J8: 2021-22 | L8: 2013-14 | M8: 2014-15 | N8: 2015-16 | O8: 2016-17 | P8: 2017-18 | Q8: 2018-19 | R8: 2019-20 | S8: 2020-21 | T8: 2021-22 | V8: 2013-14 | W8: 2014-15 | X8: 2015-16 | Y8: 2016-17 | Z8: 2017-18 | AA8: 2018-19 | AB8: 2019-20 | AC8: 2020-21 | AD8: 2021-22
A10: Data source | B10: KP90 | C10: KP90 | D10: KP90 | E10: MHSDS/ Acute | F10: MHSDS/ Acute | G10: MHSDS/ ECDS | H10: MHSDS/ ECDS | I10: MHSDS/ ECDS | J10: MHSDS/ ECDS | L10: KP90 | M10: KP90 | N10: KP90 | O10: MHSDS/ Acute | P10: MHSDS/ Acute | Q10: MHSDS/ ECDS | R10: MHSDS7 | S10: MHSDS7 | T10: MHSDS7 | V10: KP90 | W10: KP90 | X10: KP90 | Y10: MHSDS | Z10: MHSDS | AA10: MHSDS | AB10: MHSDS7 | AC10: MHSDS7 | AD10: MHSDS7
A12: All detentions1,2 | B12: 53176 | C12: 58399 | D12: 63622 | E12: 45864 | F12: 49551 | G12: 49988 | H12: 50893 | I12: 53239 | J12: tag_table1a_1 | L12: 48014 | M12: 51969 | N12: 56594 | O12: 43050 | P12: 46552 | Q12: 46837 | R12: 47975 | S12: 50518 | T12: tag_table1a_9 | V12: 5162 | W12: 6430 | X12: 7028 | Y12: 2814 | Z12: 2999 | AA12: 3151 | AB12: 2918 | AC12: 2721 | AD12: tag_table1a_17
A14: Detentions on admission to hospital3,4 | B14: 34806 | C14: 37709 | D14: 40785 | E14: 25474 | F14: 27971 | G14: 30478 | H14: 32320 | I14: 35275 | J14: tag_table1a_2 | L14: 30574 | M14: 32524 | N14: 35403 | O14: 24416 | P14: 26824 | Q14: 29230 | R14: 31280 | S14: 34265 | T14: tag_table1a_10 | V14: 4232 | W14: 5185 | X14: 5382 | Y14: 1058 | Z14: 1147 | AA14: 1248 | AB14: 1040 | AC14: 1010 | AD14: tag_table1a_18
A16: All detentions under Part II of the Mental Health Act | B16: 32781 | C16: 35444 | D16: 38873 | E16: 25224 | F16: 27690 | G16: 30114 | H16: 32011 | I16: 34863 | J16: tag_table1a_3 | L16: 29116 | M16: 30883 | N16: 33912 | O16: 24216 | P16: 26590 | Q16: 28916 | R16: 31012 | S16: 33886 | T16: tag_table1a_11 | V16: 3665 | W16: 4561 | X16: 4961 | Y16: 1008 | Z16: 1100 | AA16: 1198 | AB16: 999 | AC16: 977 | AD16: tag_table1a_19
A17: Section 2 | B17: 25300 | C17: 27754 | D17: 30627 | E17: 21621 | F17: 23864 | G17: 25963 | H17: 27968 | I17: 30407 | L17: 23326 | M17: 25293 | N17: 27705 | O17: 20823 | P17: 22994 | Q17: 25021 | R17: 27093 | S17: 29570 | V17: 1974 | W17: 2461 | X17: 2922 | Y17: 798 | Z17: 870 | AA17: 942 | AB17: 875 | AC17: 837
A18: Section 3 | B18: 7481 | C18: 7690 | D18: 8246 | E18: 3603 | F18: 3826 | G18: 4151 | H18: 4043 | I18: 4456 | L18: 5790 | M18: 5590 | N18: 6207 | O18: 3393 | P18: 3596 | Q18: 3895 | R18: 3919 | S18: 4316 | V18: 1691 | W18: 2100 | X18: 2039 | Y18: 210 | Z18: 230 | AA18: 256 | AB18: 124 | AC18: 140
A20: All detentions under Part III of the Mental Health Act | B20: 1847 | C20: 1930 | D20: 1696 | E20: 158 | F20: 203 | G20: 236 | H20: 221 | I20: 222 | J20: tag_table1a_4 | L20: 1317 | M20: 1332 | N20: 1317 | O20: 110 | P20: 157 | Q20: 189 | R20: 181 | S20: 191 | T20: tag_table1a_12 | V20: 530 | W20: 598 | X20: 379 | Y20: 48 | Z20: 46 | AA20: 47 | AB20: 40 | AC20: 31 | AD20: tag_table1a_20
A21: Section 35 | B21: 77 | C21: 75 | D21: 40 | E21: 8 | F21: 8 | G21: 2 | H21: 3 | I21: 4 | L21: 72 | M21: 67 | N21: 35 | O21: 7 | P21: 7 | Q21: 2 | R21: 3 | S21: 4 | V21: 5 | W21: 8 | X21: 5 | Y21: 1 | Z21: 1 | AA21: 0 | AB21: 0 | AC21: 0
A22: Section 36 | B22: 22 | C22: 15 | D22: 17 | E22: 0 | F22: 1 | G22: 3 | H22: 5 | I22: 7 | L22: 18 | M22: 12 | N22: 15 | O22: 0 | P22: 0 | Q22: 3 | R22: 5 | S22: 7 | V22: 4 | W22: 3 | X22: 2 | Y22: 0 | Z22: 1 | AA22: 0 | AB22: 0 | AC22: 0
A23: Section 37 (with S41 restrictions) | B23: 448 | C23: 486 | D23: 415 | E23: 26 | F23: 31 | G23: 46 | H23: 42 | I23: 25 | L23: 255 | M23: 278 | N23: 264 | O23: 12 | P23: 10 | Q23: 26 | R23: 30 | S23: 18 | V23: 193 | W23: 208 | X23: 151 | Y23: 14 | Z23: 21 | AA23: 20 | AB23: 12 | AC23: 7
A24: Section 37 (without S41 restrictions) | B24: 315 | C24: 307 | D24: 223 | E24: 21 | F24: 17 | G24: 20 | H24: 20 | I24: 25 | L24: 197 | M24: 151 | N24: 143 | O24: 11 | P24: 10 | Q24: 12 | R24: 15 | S24: 20 | V24: 118 | W24: 156 | X24: 80 | Y24: 10 | Z24: 7 | AA24: 8 | AB24: 5 | AC24: 5
A25: Section 45A | B25: 2 | C25: 9 | D25: 7 | E25: 0 | F25: 0 | G25: 0 | H25: 4 | I25: 6 | L25: 1 | M25: 6 | N25: 6 | O25: 0 | P25: 0 | Q25: 0 | R25: 4 | S25: 6 | V25: 1 | W25: 3 | X25: 1 | Y25: 0 | Z25: 0 | AA25: 0 | AB25: 0 | AC25: 0
A26: Section 47 (with S49 restrictions) | B26: 414 | C26: 429 | D26: 385 | E26: 41 | F26: 67 | G26: 49 | H26: 49 | I26: 59 | L26: 317 | M26: 324 | N26: 321 | O26: 37 | P26: 63 | Q26: 43 | R26: 43 | S26: 51 | V26: 97 | W26: 105 | X26: 64 | Y26: 4 | Z26: 4 | AA26: 6 | AB26: 6 | AC26: 8
A27: Section 47 (without S49 restrictions) | B27: 43 | C27: 60 | D27: 32 | E27: 2 | F27: 3 | G27: 4 | H27: 8 | I27: 5 | L27: 31 | M27: 38 | N27: 22 | O27: 1 | P27: 2 | Q27: 2 | R27: 5 | S27: 4 | V27: 12 | W27: 22 | X27: 10 | Y27: 1 | Z27: 1 | AA27: 2 | AB27: 3 | AC27: 1
A28: Section 48 (with S49 restrictions) | B28: 394 | C28: 440 | D28: 465 | E28: 46 | F28: 59 | G28: 69 | H28: 57 | I28: 67 | L28: 322 | M28: 374 | N28: 420 | O28: 36 | P28: 52 | Q28: 62 | R28: 49 | S28: 59 | V28: 72 | W28: 66 | X28: 45 | Y28: 10 | Z28: 7 | AA28: 7 | AB28: 8 | AC28: 8
A29: Section 48 (without S49 restrictions) | B29: 11 | C29: 3 | D29: 5 | E29: 6 | F29: 2 | G29: 1 | H29: 0 | I29: 1 | L29: 11 | M29: 3 | N29: 5 | O29: 1 | P29: 0 | Q29: 1 | R29: 0 | S29: 1 | V29: 0 | W29: 0 | X29: - | Y29: 5 | Z29: 2 | AA29: 0 | AB29: 0 | AC29: 0
A30: Detentions under other sections (38, 44 and 46) | B30: 121 | C30: 106 | D30: 107 | E30: 8 | F30: 15 | G30: 42 | H30: 33 | I30: 23 | L30: 93 | M30: 79 | N30: 86 | O30: 5 | P30: 13 | Q30: 38 | R30: 27 | S30: 21 | V30: 28 | W30: 27 | X30: 21 | Y30: 3 | Z30: 2 | AA30: 4 | AB30: 6 | AC30: 2
A32: Detentions under previous legislation (Fifth Schedule) and other Acts | B32: 178 | C32: 335 | D32: 216 | E32: 17 | F32: 10 | G32: 100 | H32: 88 | I32: 190 | J32: tag_table1a_5 | L32: 141 | M32: 309 | N32: 174 | O32: 15 | P32: 9 | Q32: 97 | R32: 87 | S32: 188 | T32: tag_table1a_13 | V32: 37 | W32: 26 | X32: 42 | Y32: 2 | Z32: 1 | AA32: 3 | AB32: 1 | AC32: 2 | AD32: tag_table1a_21
A34: Detentions following admission to hospital3,5,6 | B34: 14087 | C34: 16078 | D34: 17181 | E34: 17565 | F34: 18349 | G34: 15834 | H34: 14576 | I34: 13619 | J34: tag_table1a_6 | L34: 13254 | M34: 14938 | N34: 15622 | O34: 15846 | P34: 16542 | Q34: 13979 | R34: 12731 | S34: 11996 | T34: tag_table1a_14 | V34: 833 | W34: 1140 | X34: 1559 | Y34: 1719 | Z34: 1807 | AA34: 1855 | AB34: 1845 | AC34: 1623 | AD34: tag_table1a_22
A35: Informal to section 2 | B35: 4097 | C35: 5079 | D35: 5678 | E35: 7107 | F35: 7697 | G35: 5769 | H35: 5147 | I35: 4981 | L35: 3834 | M35: 4600 | N35: 4919 | O35: 6138 | P35: 6624 | Q35: 4759 | R35: 4071 | S35: 4035 | V35: 263 | W35: 479 | X35: 759 | Y35: 969 | Z35: 1073 | AA35: 1010 | AB35: 1076 | AC35: 946
A36: Informal to section 3 | B36: 3483 | C36: 4077 | D36: 4303 | E36: 5239 | F36: 5164 | G36: 4983 | H36: 4787 | I36: 4381 | L36: 3298 | M36: 3840 | N36: 4079 | O36: 4700 | P36: 4639 | Q36: 4409 | R36: 4266 | S36: 3893 | V36: 185 | W36: 237 | X36: 224 | Y36: 539 | Z36: 525 | AA36: 574 | AB36: 521 | AC36: 488
A37: Section 5(2) to 2 | B37: 3707 | C37: 4015 | D37: 4121 | E37: 3008 | F37: 3135 | G37: 2736 | H37: 2488 | I37: 2335 | L37: 3457 | M37: 3751 | N37: 3776 | O37: 2884 | P37: 3013 | Q37: 2583 | R37: 2344 | S37: 2234 | V37: 250 | W37: 264 | X37: 345 | Y37: 124 | Z37: 122 | AA37: 153 | AB37: 144 | AC37: 101
A38: Section 5(2) to 3 | B38: 2414 | C38: 2489 | D38: 2631 | E38: 2114 | F38: 2236 | G38: 2225 | H38: 2060 | I38: 1855 | L38: 2292 | M38: 2348 | N38: 2417 | O38: 2033 | P38: 2150 | Q38: 2112 | R38: 1963 | S38: 1774 | V38: 122 | W38: 141 | X38: 214 | Y38: 81 | Z38: 86 | AA38: 113 | AB38: 97 | AC38: 81
A39: Section 5(4) to 2 | B39: 54 | C39: 56 | D39: 51 | E39: 28 | F39: 30 | G39: 27 | H39: 26 | I39: 22 | L39: 49 | M39: 54 | N39: 47 | O39: 24 | P39: 30 | Q39: 24 | R39: 25 | S39: 22 | V39: 5 | W39: 2 | X39: 4 | Y39: 4 | Z39: 0 | AA39: 3 | AB39: 1 | AC39: 0
A40: Section 5(4) to 3 | B40: 44 | C40: 43 | D40: 40 | E40: 16 | F40: 20 | G40: 24 | H40: 19 | I40: 9 | L40: 43 | M40: 41 | N40: 39 | O40: 16 | P40: 20 | Q40: 24 | R40: 19 | S40: 8 | V40: 1 | W40: 2 | X40: 1 | Y40: 0 | Z40: 0 | AA40: 0 | AB40: 0 | AC40: 1
A41: Section 4 to 2 | B41: 260 | C41: 277 | D41: 331 | E41: 41 | F41: 50 | G41: 38 | H41: 36 | I41: 32 | L41: 254 | M41: 262 | N41: 319 | O41: 39 | P41: 49 | Q41: 36 | R41: 30 | S41: 26 | V41: 6 | W41: 15 | X41: 12 | Y41: 2 | Z41: 1 | AA41: 2 | AB41: 6 | AC41: 6
A42: Section 4 to 3 | B42: 28 | C42: 42 | D42: 26 | E42: 12 | F42: 18 | G42: 32 | H42: 14 | I42: 5 | L42: 27 | M42: 42 | N42: 26 | O42: 12 | P42: 18 | Q42: 32 | R42: 14 | S42: 5 | V42: 1 | W42: 0 | X42: 0 | Y42: 0 | Z42: 0 | AA42: 0 | AB42: 0 | AC42: 0
A44: Detentions following use of Place of Safety Order | B44: 2882 | C44: 3185 | D44: 4099 | E44: 2619 | F44: 2983 | G44: 3504 | H44: 3805 | I44: 4151 | J44: tag_table1a_7 | L44: 2837 | M44: 3131 | N44: 4051 | O44: 2589 | P44: 2941 | Q44: 3456 | R44: 3773 | S44: 4063 | T44: tag_table1a_15 | V44: 45 | W44: 54 | X44: 48 | Y44: 30 | Z44: 42 | AA44: 48 | AB44: 32 | AC44: 88 | AD44: tag_table1a_23
A45: Section 135 to 2 | B45: 0 | C45: 0 | D45: 0 | E45: 219 | F45: 317 | G45: 388 | H45: 470 | I45: 454 | L45: 0 | M45: 0 | N45: 0 | O45: 217 | P45: 309 | Q45: 378 | R45: 464 | S45: 428 | V45: 0 | W45: 0 | X45: 0 | Y45: 2 | Z45: 8 | AA45: 10 | AB45: 6 | AC45: 26
A46: Section 135 to 3 | B46: 0 | C46: 0 | D46: 0 | E46: 55 | F46: 97 | G46: 99 | H46: 130 | I46: 111 | L46: 0 | M46: 0 | N46: 0 | O46: 54 | P46: 91 | Q46: 93 | R46: 127 | S46: 94 | V46: 0 | W46: 0 | X46: 0 | Y46: 1 | Z46: 6 | AA46: 6 | AB46: 3 | AC46: 17
A47: Section 136 to 2 | B47: 2587 | C47: 2882 | D47: 3660 | E47: 2118 | F47: 2324 | G47: 2713 | H47: 2920 | I47: 3278 | L47: 2551 | M47: 2836 | N47: 3614 | O47: 2093 | P47: 2298 | Q47: 2684 | R47: 2898 | S47: 3235 | V47: 36 | W47: 46 | X47: 46 | Y47: 25 | Z47: 26 | AA47: 29 | AB47: 22 | AC47: 43
A48: Section 136 to 3 | B48: 295 | C48: 303 | D48: 439 | E48: 227 | F48: 245 | G48: 304 | H48: 285 | I48: 308 | L48: 286 | M48: 295 | N48: 437 | O48: 225 | P48: 243 | Q48: 301 | R48: 284 | S48: 306 | V48: 9 | W48: 8 | X48: 2 | Y48: 2 | Z48: 2 | AA48: 3 | AB48: 1 | AC48: 2
A50: Detentions following revocation of CTO | B50: 1401 | C50: 1427 | D50: 1557 | E50: 214 | F50: 257 | G50: 199 | H50: 206 | I50: 223 | J50: tag_table1a_8 | L50: 1349 | M50: 1376 | N50: 1518 | O50: 207 | P50: 254 | Q50: 199 | R50: 204 | S50: 221 | T50: tag_table1a_16 | V50: 52 | W50: 51 | X50: 39 | Y50: 7 | Z50: 3 | AA50: 0 | AB50: 2 | AC50: 2 | AD50: tag_table1a_24
A53: Sources: KP90 (2013-14 to 2015-16), MHSDS/MHA Acute (2016-17 to 2017-18), MHSDS/ECDS (2018-19 to 2021-22) - NHS Digital
A55: Footnotes: 1) For 2016-17 data, there is a discrepancy of 8 detentions between the 'All detentions' figure and the sum of the individual categories. For 2017-18 data, there is a discrepancy of 9 detentions between the 'All detentions' figure and the sum of the individual categories. For 2018-19 data, there is a discrepency of 15 detentions between the 'All detentions' figure and the sum of the individual categories. For 2019-20 data, there is a discrepancy of 9 detentions between the 'All detentions' figure and the sum of the individual categories. For 2021-22 data, there is a discrepency of 29 detentions between the 'All detentions' figure and the sum of the individual categories. This is due to difficulties in determining the sequence of events in these cases, using the record-level MHSDS data. 2) In 2016-17, 7,091 transfers on section were recorded. Of these 5,528 were recorded by NHS providers and 1,563 were recorded by Independent Sector providers. In 2017-18, 4,747 transfers on section were recorded. Of these 3,783 were recorded by NHS providers and 964 were recorded by Independent Sector providers. In 2018-19, 4,909 transfers on section were recorded. Of these 3,900 were recorded by NHS providers and 1,009 were recorded by Independent Sector providers. In 2019-20, 5,253 transfers on section were recorded. Of these 4,268 were recorded by NHS providers and 985 were recorded by Independent Sector providers. In 2021-22, 4,807 transfers on section were recorded. Of these 3,736 were recorded by NHS providers and 1,071 were recorded by Independent Sector providers. 3) From 2016-17, numbers for detentions on admission and detentions following admission to hospital are affected by the quality of time recording in MHSDS. Further details are provided in the Background Data Quality Report. 4) For 2016-17 and 2017-18, this total is higher than the sum of components due to the inclusion of data from the Acute collection for 'any other formal admissions', which cannot be allocated to any of the components. 5) For 2017-18, 2019-20 and 2021-22, there is a discrepancy of one detention between the total and components due to a data quality issue. 6) Detentions recorded in ECDS have been all been included in the Detentions on Admission category only. This is because it has not been possible to conclude whether the detention occured on admission or following admission. The detentions that occured appear to have happened on the same day but further analysis and improved data quality is required to improve reporting of detentions on admission and following admission in ECDS. 7) Data for NHS and Independent provider splits is only displayed from MHSDS for 2021-22. This is due to small numbers in the ECDS data for Independent providers.
...

Sheet Table 1b
A1: Table 1b
A3: Detentions under the Mental Health Act 1983, by age group and gender, 2021-22
A5: This table shows the numbers and rates of detention by age group and gender, for 2021-22. Detentions data are incomplete in 2021-22 so the counts and rates shown are lower than the true figures. However, broad comparisons between groups are valid. Population figures are ONS mid-year population estimates 2020.
B7: Number of detentions | C7: Base Population3 | D7: Crude rate per 100,000 population
A9: All1 | B9: tag_table1b_1
A11: All age groups (where recorded)2 | B11: tag_table1b_2
A13: 17 and under | B13: tag_table1b_3
A14: 15 and under
A15: 16 to 17
A17: 18 and over | B17: tag_table1b_4
A18: 18 to 34
A19: 35 to 49
A20: 50 to 64
A21: 65 and over
A23: All genders (where recorded)2 | B23: tag_table1b_5
A24: Male
A25: Female
A26: Non-Binary - based on Gender identity field
A27: Other (not listed) - based on Gender identity field
A28: Indeterminate - based on Person stated gender field
A31: Sources: MHSDS / MHA Acute 2021-22 - NHS Digital, ONS mid-year population estimates 2020.
A33: Footnotes 1) The total for 'All' is calculated from both the MHSDS and ECDS collections. It includes detentions where the age and gender details were not submitted. The totals for 'All age groups' and 'All genders' are from MHSDS only since the ECDS collection does not allow for further demographic breakdowns. 2) The total for 'All genders' is lower than for 'All' as these exclude records where these characteristics were either recorded as 'Not stated' and 'Not known' or where they were not submitted. 3) ONS mid-year population estimates 2020.
A35: Copyright © 2021, Health and Social Care Information Centre. The Health and Social Care Information Centre is a non-departmental body created by statute, also known as NHS Digital
A36: This work remains the sole and exclusive property of the Health and Social Information Centre and may only be reproduced where there is explicit reference to the ownership of the Health and Social Care Information Centre.

Sheet Table 1c
A1: Table 1c
A3: Detentions under the Mental Health Act 1983, by ethnicity, 2021-22
A5: This table shows the numbers and rates of detention by ethnicity, for 2021-22. Detentions data are incomplete in 2021-22 so the counts and rates shown are lower than the true figures. However, broad comparisons between groups are valid. Population figures are from the 2011 Census as ONS mid-year estimates do not include updates for ethnicity.
A6: The population figures use 2011 Census categories. The 2011 Census introduced the new Gypsy or Irish Traveller and Arab categories. MHSDS does not allow for data to be submitted with these new categories and as such for the purpose of analysis the new Gypsy or Irish Traveller and Arab categories have not been included. The population figure for Gypsy or Irish Traveller is included in the total population figures for the broad category of White and the population figure for Arab is included in the population figures for Any Other Ethnic Group category. The inclusion of these groups could affect the rate for the Any other ethnic group. Although Gypsy and Arab are identified in the population figures, since these groups are not separately identified in the MHSDS, we cannot produce separate rates for these groups. We also do not know which categories these people would have identified as belonging to in the MHSDS. For example, an Arab person may have self-identified as Asian or Any Other Ethnic group and the way this affects the rates shown is unknown. The broad groupings shown below follow the 2001 Census groupings, which are still used in the NHS. However the 2011 census re-positions 'Chinese' from Any other ethnic group to Asian/Asian British. This means that figures using 2011 Census categories will not be comparable with any using 2001 Census categories for 'Any Other Ethnic Group' and 'Asian/Asian British'.
B8: Number of detentions | C8: Base Population3 | D8: Crude rate per 100,000 population | E8: Standardised rate per 100,000 population | F8: Confidence Interval
A10: All1 | B10: tag_table1c_1
A12: All ethnicities (where recorded)2 | B12: tag_table1c_2
A14: Ethnicity
A15: White | B15: tag_table1c_3
A16: White British
A17: White Irish
A18: Any Other White Background
A19: Gypsy or Irish Traveller
A21: Mixed | B21: tag_table1c_4
A22: White and Black Caribbean
A23: White and Black African
A24: White and Asian
A25: Any Other Mixed Background
A27: Asian or Asian British | B27: tag_table1c_5
A28: Indian
A29: Pakistani
A30: Bangladeshi
A31: Any Other Asian Background
A33: Black or Black British | B33: tag_table1c_6
A34: African
A35: Caribbean
A36: Any Other Black Background
A38: Other Ethnic Groups | B38: tag_table1c_7
A39: Chinese
A40: Any Other Ethnic Group
A41: Arab
A44: Sources: MHSDS, ECDS 2021-22 - NHS Digital
A46: Footnotes 1) The total for 'All' is calculated from both the MHSDS and ECDS collections. It includes detentions where the ethnicity was not submitted.Further breakdowns are from MHSDS only since the ECDS collection does not allow for further demographic breakdowns. 2) The total for 'All ethnicities' is lower than for 'All' as it excludes records where any of age, gender or ethnicity was either recorded as 'Not stated' and 'Not known' or where it was not submitted. This information was required for direct standardisation of population-based rates. 3) ONS Census 2011 - table reference: DC2101EW - Ethnic group by sex by age, QS211EW - Ethnic group (detailed)
A47: https://www.nomisweb.co.uk/census/2011/LC2101EW/view/2092957699?rows=c_ethpuk11&cols=c_sex
A49: Copyright © 2021, Health and Social Care Information Centre. The Health and Social Care Information Centre is a non-departmental body created by statute, also known as NHS Digital
A50: This work remains the sole and exclusive property of the Health and Social Information Centre and may only be reproduced where there is explicit reference to the ownership of the Health and Social Care Information Centre.

Sheet Table 1d
A1: Table 1d
A3: Detentions under the Mental Health Act 1983, by Sustainability and Transformation Partnership (STP) area, 2021-22
A5: This table shows the numbers and rates of detention by STP area, for 2021-22. Detentions data are incomplete in 2021-22 so the counts and rates shown are lower than the true figures. Missing data for particular providers means that comparisons between STP areas must be made with caution, as areas with low completion rates will record low rates of detention which are not representative of the true picture. For further details of shortfalls in coverage, please refer to the Background Data Quality Report. Population figures are based on ONS mid-2019 population estimates for 2020 CCG mapped to STP.
B7: Sustainability and Transformation Partnership area | C7: Number of detentions | D7: Base Population2 | E7: Crude rate per 100,000 population
A9: All1 | C9: tag_table1d_1
A11: All STPs | C11: tag_table1d_2
A13: tag_table1d_3
A58: Sources: MHSDS, ECDS 2021-22 - NHS Digital
A60: Footnotes 1) The total for 'All' is calculated from both the MHSDS and ECDS collections. It includes detentions where the STP could not be derived. Further breakdowns are from MHSDS only since the ECDS collection does not allow for further breakdowns and therefore STP could not be derived from this data. 2) ONS mid-2019 population estimates for 2020 CCG have been mapped to STP
A62: Copyright © 2021, Health and Social Care Information Centre. The Health and Social Care Information Centre is a non-departmental body created by statute, also known as NHS Digital
A63: This work remains the sole and exclusive property of the Health and Social Information Centre and may only be reproduced where there is explicit reference to the ownership of the Health and Social Care Information Centre.

Sheet Table 1e
A1: Table 1e
A3: Counts and rates of Detention under the Mental Health Act 1983, cross-tabulated by age group, ethnicity and gender, 2021-22
A5: This table shows the number of detentions across gender, age group and ethnicity for 2021-22. Detentions data are incomplete in 2021-22 so the counts shown are lower than the true figures. However, broad comparisons between groups are valid.
B7: Count | N7: Crude Rate per 100,000 population
B8: Ethnicity | H8: Gender | N8: Ethnicity | T8: Gender
B9: White | C9: Mixed | D9: Asian | E9: Black | F9: Other | H9: Male | I9: Female | J9: Non-binary | K9: Other (not listed) | L9: Indeterminate | M9: Unknown | N9: White | O9: Mixed | P9: Asian | Q9: Black | R9: Other | T9: Male | U9: Female | V9: Non-binary | W9: Other (not listed) | X9: Indeterminate | Y9: Unknown
A12: All ages and genders1 | B12: tag_table1e_1 | H12: tag_table1e_2 | N12: tag_table1e_9 | T12: tag_table1e_10
A14: Age
A15: 17 and under | B15: tag_table1e_3 | H15: tag_table1e_4 | N15: tag_table1e_11 | T15: tag_table1e_12
A16: 15 and under
A17: 16 to 17
A19: 18 and over | B19: tag_table1e_5 | H19: tag_table1e_6 | N19: tag_table1e_13 | T19: tag_table1e_14
A20: 18 to 34
A21: 35 to 49
A22: 50 to 64
A23: 65 and over
A25: Gender
A26: Male | B26: tag_table1e_7 | H26: tag_table1e_8 | N26: tag_table1e_15 | T26: tag_table1e_16
A27: Female
A28: Non-binary
A29: Other (not listed)
A30: Indeterminate
A31: Unknown
A34: Source: MHSDS
A36: Footnotes 1) Data has been excluded where any of age, gender or ethnicity was either recorded as 'Not stated' and 'Not known' or where it was not submitted. The total for 'All ages and genders' is calculated from MHSDS only since the ECDS collection does not allow for further demographic breakdowns.
A38: Copyright © 2021, Health and Social Care Information Centre. The Health and Social Care Information Centre is a non-departmental body created by statute, also known as NHS Digital
A39: This work remains the sole and exclusive property of the Health and Social Information Centre and may only be reproduced where there is explicit reference to the ownership of the Health and Social Care Information Centre.

Sheet Table 1f
A1: Table 1f
A3: Detentions under the Mental Health Act 1983, by Clinical Commissioning Group (CCG) area, 2021-22
A5: This table shows the numbers and rates of detention by CCG area, for 2021-22 Detentions data are incomplete in 2021-22 so the counts and rates shown are lower than the true figures. Population figures are ONS mid-2019 population estimates for 2020.
B7: Clinical Commissioning Group area | C7: Number of detentions | D7: Base Population1 | E7: Crude rate per 100,000 population
A9: All1 | C9: tag_table1f_1
A11: All CCGs | C11: tag_table1f_2
A13: tag_table1f_3 | D13: =IFERROR(VLOOKUP(A13,#REF!,3,FALSE),"-") -> - | E13: =IFERROR(C13/D13*100000,"-") -> -
D14: =IFERROR(VLOOKUP(A14,#REF!,3,FALSE),"-") -> - | E14: =IFERROR(C14/D14*100000,"-") -> -
D15: =IFERROR(VLOOKUP(A15,#REF!,3,FALSE),"-") -> - | E15: =IFERROR(C15/D15*100000,"-") -> -
D16: =IFERROR(VLOOKUP(A16,#REF!,3,FALSE),"-") -> - | E16: =IFERROR(C16/D16*100000,"-") -> -
D17: =IFERROR(VLOOKUP(A17,#REF!,3,FALSE),"-") -> - | E17: =IFERROR(C17/D17*100000,"-") -> -
D18: =IFERROR(VLOOKUP(A18,#REF!,3,FALSE),"-") -> - | E18: =IFERROR(C18/D18*100000,"-") -> -
D19: =IFERROR(VLOOKUP(A19,#REF!,3,FALSE),"-") -> - | E19: =IFERROR(C19/D19*100000,"-") -> -
D20: =IFERROR(VLOOKUP(A20,#REF!,3,FALSE),"-") -> - | E20: =IFERROR(C20/D20*100000,"-") -> -
D21: =IFERROR(VLOOKUP(A21,#REF!,3,FALSE),"-") -> - | E21: =IFERROR(C21/D21*100000,"-") -> -
D22: =IFERROR(VLOOKUP(A22,#REF!,3,FALSE),"-") -> - | E22: =IFERROR(C22/D22*100000,"-") -> -
D23: =IFERROR(VLOOKUP(A23,#REF!,3,FALSE),"-") -> - | E23: =IFERROR(C23/D23*100000,"-") -> -
D24: =IFERROR(VLOOKUP(A24,#REF!,3,FALSE),"-") -> - | E24: =IFERROR(C24/D24*100000,"-") -> -
D25: =IFERROR(VLOOKUP(A25,#REF!,3,FALSE),"-") -> - | E25: =IFERROR(C25/D25*100000,"-") -> -
... D119: =IFERROR(VLOOKUP(A119,#REF!,3,FALSE),"-") -> - | E119: =IFERROR(C119/D119*100000,"-") -> -
A121: Sources: MHSDS, ECDS 2021-22 - NHS Digital
A123: Footnotes 1) ONS mid-2019 population estimates for 2020
A125: Copyright © 2021, Health and Social Care Information Centre. The Health and Social Care Information Centre is a non-departmental body created by statute, also known as NHS Digital
A126: This work remains the sole and exclusive property of the Health and Social Information Centre and may only be reproduced where there is explicit reference to the ownership of the Health and Social Care Information Centre.

Sheet Table 1g
A1: Table 1g
A3: Detentions under the Mental Health Act 1983, by IMD decile, 2021-22
A5: This table shows the numbers and rates of detention by IMD Decile, for 2021-22. Detentions data are incomplete in 2021-22 so the counts and rates shown are lower than the true figures. Population figures are ONS mid-year population estimates 2017.
B7: IMD Decile | C7: Number of detentions2 | D7: Base Population3 | E7: Crude rate per 100,000 population
A9: All1 | C9: tag_table1g_1
C11: tag_table1g_2
B13: tag_table1g_3
A26: Sources: MHSDS, ECDS 2021-22 - NHS Digital
A28: Footnotes 1) The total for 'All' is calculated from both the MHSDS and ECDS collections. It includes detentions where the IMD decile could not be derived. 2) The sum of the IMD decile breakdown only relates to MHSDS and not ECDS and so will not equal the total for 'All' which includes data from both collections. 3) ONS mid-year population estimates 2017
A30: Copyright © 2021, Health and Social Care Information Centre. The Health and Social Care Information Centre is a non-departmental body created by statute, also known as NHS Digital
A31: This work remains the sole and exclusive property of the Health and Social Information Centre and may only be reproduced where there is explicit reference to the ownership of the Health and Social Care Information Centre.

Sheet Table 1h
A1: Table 1h
A3: Detentions under the Mental Health Act 1983, by IMD decile and ethnicity, 2021-22
A5: This table shows the numbers detention by Ethncity and IMD, for 2021-22. Percentages are based on the row totals to allow broad comparisons between ethnic groups. Detentions data are incomplete in 2021-22 so the counts and rates shown are lower than the true figures.
C8: 01 Least deprived | D8: 02 Less deprived | E8: 03 Less deprived | F8: 04 Less deprived | G8: 05 Less deprived | H8: 06 More deprived | I8: 07 More deprived | J8: 08 More deprived | K8: 09 More deprived | L8: 10 Most deprived | M8: Not stated/Not known/Invalid | O8: 01 Least deprived (%) | P8: 02 Less deprived (%) | Q8: 03 Less deprived (%) | R8: 04 Less deprived (%) | S8: 05 Less deprived (%) | T8: 06 More deprived (%) | U8: 07 More deprived (%) | V8: 08 More deprived (%) | W8: 09 More deprived (%) | X8: 10 Most deprived (%) | Y8: Not stated/Not known/Invalid (%)
A10: Ethnicity
A11: White | C11: tag_table1h_1 | O11: tag_table1h_6
A12: White British
A13: White Irish
A14: Any Other White Background
A15: Gypsy or Irish Traveller | C15: - | D15: - | E15: - | F15: - | G15: - | H15: - | I15: - | J15: - | K15: - | L15: - | M15: - | O15: - | P15: - | Q15: - | R15: - | S15: - | T15: - | U15: - | V15: - | W15: - | X15: - | Y15: -
A17: Mixed | C17: tag_table1h_2 | O17: tag_table1h_7
A18: White and Black Caribbean
A19: White and Black African
A20: White and Asian
A21: Any Other Mixed Background
A23: Asian or Asian British | C23: tag_table1h_3 | O23: tag_table1h_8
A24: Indian
A25: Pakistani
A26: Bangladeshi
A27: Any Other Asian Background
A29: Black or Black British | C29: tag_table1h_4 | O29: tag_table1h_9
A30: African
A31: Caribbean
A32: Any Other Black Background
A34: Other Ethnic Groups | C34: tag_table1h_5 | O34: tag_table1h_10
A35: Chinese
A36: Any Other Ethnic Group
A37: Arab | C37: - | D37: - | E37: - | F37: - | G37: - | H37: - | I37: - | J37: - | K37: - | L37: - | M37: - | O37: - | P37: - | Q37: - | R37: - | S37: - | T37: - | U37: - | V37: - | W37: - | X37: - | Y37: -
A40: Sources: MHSDS - NHS Digital
A42: Copyright © 2021, Health and Social Care Information Centre. The Health and Social Care Information Centre is a non-departmental body created by statute, also known as NHS Digital
A43: This work remains the sole and exclusive property of the Health and Social Information Centre and may only be reproduced where there is explicit reference to the ownership of the Health and Social Care Information Centre.

Sheet Table 1i
A1: Table 1i
A3: Detentions under the Mental Health Act 1983, by Sustainability and Transformation Partnership (STP) area by age group and gender, 2021-22
A5: This table shows the numbers and rates of detention by STP area, for 2021-22. Detentions data are incomplete in 2021-22 so the counts and rates shown are lower than the true figures. Missing data for particular providers means that comparisons between STP areas must be made with caution, as areas with low completion rates will record low rates of detention which are not representative of the true picture. For further details of shortfalls in coverage, please refer to the Background Data Quality Report. Demographic breakdowns use the last set of person characteristics (e.g. age, gender or ethnicity) recorded in the year. This is to prevent instances where one person may have been recorded with different characteristics in different submissions. By taking the latest available demographics this ensures each person is consistently assigned with one age, gender and ethnic group. Caution should therefore be used when interpreting small numbers due to possible data quality issues. Population figures are based on ONS mid-2019 population estimates for 2020 CCG mapped to STP.
A7: Sustainability and Transformation Partnership area | D7: Gender | J7: Age Group
D8: Male | E8: Female | F8: Non-binary | G8: Other (not listed) | H8: Indeterminate | I8: Unknown | J8: 15 and under | K8: 16 to 17 | L8: 18 to 34 | M8: 35 to 49 | N8: 50 to 64 | O8: 65 and over
A11: All STPs | C11: Number of detentions | D11: tag_table1i_1 | J11: tag_table1i_2
C12: Base Population2
C13: Crude rate per 100,000 population
A14: STP
A15: tag_table1i_3
A146: Sources: MHSDS, ECDS 2021-22 - NHS Digital
A148: Footnotes 1) The total for 'All' is calculated from both the MHSDS and ECDS collections. It includes detentions where the STP could not be derived. Further breakdowns are from MHSDS only since the ECDS collection does not allow for further breakdowns and therefore STP could not be derived from this data. 2) ONS mid-2019 population estimates for 2020 CCG have been mapped to STP
A150: Copyright © 2021, Health and Social Care Information Centre. The Health and Social Care Information Centre is a non-departmental body created by statute, also known as NHS Digital
A151: This work remains the sole and exclusive property of the Health and Social Information Centre and may only be reproduced where there is explicit reference to the ownership of the Health and Social Care Information Centre.

Sheet Table 1j
A1: Table 1j
A3: Detentions under the Mental Health Act 1983, by Sustainability and Transformation Partnership (STP) area by ethnicity and deprivation decile, 2021-22
A4: This table shows the numbers and rates of detention by STP area, for 2021-22. Detentions data are incomplete in 2021-22 so the counts and rates shown are lower than the true figures. Missing data for particular providers means that comparisons between STP areas must be made with caution, as areas with low completion rates will record low rates of detention which are not representative of the true picture. For further details of shortfalls in coverage, please refer to the Background Data Quality Report. Demographic breakdowns use the last set of person characteristics (e.g. age, gender or ethnicity) recorded in the year. This is to prevent instances where one person may have been recorded with different characteristics in different submissions. By taking the latest available demographics this ensures each person is consistently assigned with one age, gender and ethnic group. Caution should therefore be used when interpreting small numbers due to possible data quality issues. Population figures are based on ONS mid-2019 population estimates for 2020 CCG mapped to STP.
A6: Sustainability and Transformation Partnership area | D6: Ethnicity | I6: IMD Decile
D7: White | E7: Mixed | F7: Asian | G7: Black | H7: Other | I7: 01 Least deprived | J7: 02 Less deprived | K7: 03 Less deprived | L7: 04 Less deprived | M7: 05 Less deprived | N7: 06 More deprived | O7: 07 More deprived | P7: 08 More deprived | Q7: 09 More deprived | R7: 10 Most deprived | S7: Not stated/Not known/Invalid
A10: All STPs | C10: Number of detentions | D10: tag_table1j_1 | I10: tag_table1j_2
C11: Base Population2
C12: Crude rate per 100,000 population
A13: STP
A14: tag_table1j_3
A146: Sources: MHSDS, ECDS 2021-22 - NHS Digital
A148: Footnotes 1) The total for 'All' is calculated from both the MHSDS and ECDS collections. It includes detentions where the STP could not be derived. Further breakdowns are from MHSDS only since the ECDS collection does not allow for further breakdowns and therefore STP could not be derived from this data. 2) ONS mid-2019 population estimates for 2020 CCG have been mapped to STP
A150: Copyright © 2021, Health and Social Care Information Centre. The Health and Social Care Information Centre is a non-departmental body created by statute, also known as NHS Digital
A151: This work remains the sole and exclusive property of the Health and Social Information Centre and may only be reproduced where there is explicit reference to the ownership of the Health and Social Care Information Centre.

Sheet Table 2a
A1: Table 2a
A3: Uses of Short Term Orders under the Mental Health Act 1983 by provider type, 2013-14 to 2021-22
A5: Notes:
A6: This table shows the number of uses of Sections 4, 5(2), 5(4), 135 and 136 during each period. From 2016-17, data is not comparable to previous years due to the change in data source from the KP90 collection to the MHSDS. For further details please refer to the Background Data Quality Report.
A7: Short-term detention orders are those of no greater than 24 hours' duration, except where a doctor has approved a further 12 hour extension. Prior to December 2017, the time limit for these orders was 72 hours. The figures for Place of Safety orders only include those where the ‘place of safety’ was a hospital. Orders made where the ‘place of safety’ was a police station are reported separately by the Home Office. Data for NHS Providers and Independent Sector Providers only includes data from MHSDS for 2021-22. This is due to small numbers in the ECDS data so these have not been included in these counts to prevent disclosure of small numbers.
L8: `
B9: All providers | L9: NHS Providers | V9: Independent Sector Providers
B10: 2013-14 | C10: 2014-15 | D10: 2015-16 | E10: 2016-17 | F10: 2017-18 | G10: 2018-19 | H10: 2019-20 | I10: 2020-21 | J10: 2021-22 | L10: 2013-14 | M10: 2014-15 | N10: 2015-16 | O10: 2016-17 | P10: 2017-18 | Q10: 2018-19 | R10: 2019-20 | S10: 2020-21 | T10: 2021-22 | V10: 2013-14 | W10: 2014-15 | X10: 2015-16 | Y10: 2016-17 | Z10: 2017-18 | AA10: 2018-19 | AB10: 2019-20 | AC10: 2020-21 | AD10: 2021-22
A12: Data source | B12: KP90 | C12: KP90 | D12: KP90 | E12: MHSDS/ Acute | F12: MHSDS/ Acute | G12: MHSDS/ ECDS | H12: MHSDS/ ECDS | I12: MHSDS/ ECDS | J12: MHSDS/ ECDS | L12: KP90 | M12: KP90 | N12: KP90 | O12: MHSDS/ Acute | P12: MHSDS/ Acute | Q12: MHSDS/ ECDS | R12: MHSDS1 | S12: MHSDS1 | T12: MHSDS1 | V12: KP90 | W12: KP90 | X12: KP90 | Y12: MHSDS | Z12: MHSDS | AA12: MHSDS/ ECDS | AB12: MHSDS1 | AC12: MHSDS1 | AD12: MHSDS1
A14: Short Term Detention Orders | B14: 28250 | C14: 31273 | D14: 35955 | E14: 25987 | F14: 28287 | G14: 29247 | H14: 29178 | I14: 29464 | J14: tag_table2a_1 | L14: 27413 | M14: 30346 | N14: 34763 | O14: 25090 | P14: 27352 | Q14: 28124 | R14: 28303 | S14: 28695 | T14: tag_table2a_5 | V14: 837 | W14: 927 | X14: 1192 | Y14: 897 | Z14: 935 | AA14: 1123 | AB14: 875 | AC14: 769 | AD14: tag_table2a_9
A16: All place of safety orders | B16: 17315 | C16: 19718 | D16: 23521 | E16: 15409 | F16: 17095 | G16: 19023 | H16: 19610 | I16: 21110 | J16: tag_table2a_2 | L16: 17050 | M16: 19402 | N16: 23131 | O16: 14988 | P16: 16574 | Q16: 18450 | R16: 19175 | S16: 20707 | T16: tag_table2a_6 | V16: 265 | W16: 316 | X16: 390 | Y16: 421 | Z16: 521 | AA16: 573 | AB16: 435 | AC16: 403 | AD16: tag_table2a_10
A17: Section 135 | B17: 307 | C17: 315 | D17: 556 | E17: 359 | F17: 556 | G17: 709 | H17: 901 | I17: 909 | L17: 305 | M17: 315 | N17: 556 | O17: 353 | P17: 537 | Q17: 677 | R17: 874 | S17: 841 | V17: 2 | W17: 0 | X17: 0 | Y17: 6 | Z17: 19 | AA17: 32 | AB17: 27 | AC17: 68
A18: Section 136 | B18: 17008 | C18: 19403 | D18: 22965 | E18: 15050 | F18: 16539 | G18: 18314 | H18: 18665 | I18: 20153 | L18: 16745 | M18: 19087 | N18: 22575 | O18: 14635 | P18: 16037 | Q18: 17773 | R18: 18257 | S18: 19818 | V18: 263 | W18: 316 | X18: 390 | Y18: 415 | Z18: 502 | AA18: 541 | AB18: 408 | AC18: 335
A20: Uses of Section 4 | B20: 326 | C20: 354 | D20: 405 | E20: 222 | F20: 263 | G20: 195 | H20: 177 | I20: 115 | J20: tag_table2a_3 | L20: 315 | M20: 327 | N20: 394 | O20: 215 | P20: 258 | Q20: 191 | R20: 176 | S20: 115 | T20: tag_table2a_7 | V20: 11 | W20: 27 | X20: 11 | Y20: 7 | Z20: 5 | AA20: 4 | AB20: 1 | AC20: 0 | AD20: tag_table2a_11
A22: All Uses of Section 5 | B22: 10609 | C22: 11201 | D22: 12029 | E22: 10356 | F22: 10929 | G22: 10029 | H22: 9391 | I22: 8235 | J22: tag_table2a_4 | L22: 10048 | M22: 10617 | N22: 11238 | O22: 9887 | P22: 10520 | Q22: 9483 | R22: 8952 | S22: 7869 | T22: tag_table2a_8 | V22: 561 | W22: 584 | X22: 791 | Y22: 469 | Z22: 409 | AA22: 546 | AB22: 439 | AC22: 366 | AD22: tag_table2a_12
A23: Section 5 (2) | B23: 8770 | C23: 9364 | D23: 10181 | E23: 9038 | F23: 9564 | G23: 8554 | H23: 7964 | I23: 7166 | L23: 8302 | M23: 8868 | N23: 9524 | O23: 8646 | P23: 9217 | Q23: 8114 | R23: 7591 | S23: 6847 | V23: 468 | W23: 496 | X23: 657 | Y23: 392 | Z23: 347 | AA23: 440 | AB23: 373 | AC23: 319
A24: Section 5 (4) | B24: 1839 | C24: 1837 | D24: 1848 | E24: 1318 | F24: 1365 | G24: 1475 | H24: 1427 | I24: 1069 | L24: 1746 | M24: 1749 | N24: 1714 | O24: 1241 | P24: 1303 | Q24: 1369 | R24: 1361 | S24: 1022 | V24: 93 | W24: 88 | X24: 134 | Y24: 77 | Z24: 62 | AA24: 106 | AB24: 66 | AC24: 47
A27: Sources: KP90 (2013-14 to 2015-16), MHSDS/MHA Acute (2016-17 to 2017-18), MHSDS/ECDS (2018-19, to 2021-22) - NHS Digital
A28: Footnotes: 1) Data for NHS and Independent provider splits is only displayed from MHSDS for 2021-22. This is due to small numbers in the ECDS data for Independent providers. 2) Totals include data from ECDS but some of the breakdowns only include MHSDS data so the sum of the breakdowns may not match the Total figures.
A30: Copyright © 2021, Health and Social Care Information Centre. The Health and Social Care Information Centre is a non-departmental body created by statute, also known as NHS Digital
A31: This work remains the sole and exclusive property of the Health and Social Information Centre and may only be reproduced where there is explicit reference to the ownership of the Health and Social Care Information Centre.

Sheet Table 2b
A1: Table 2b
A3: Uses of Short Term Detention Orders (Place of Safety Orders: Section 136) under the Mental Health Act 1983 by age group and gender, 2021-22
A6: This table shows counts and rates of uses of section 136 by age group and gender, in 2021-22. Data about uses of Section 136 are incomplete in 2021-22 so the counts and rates shown are lower than the true figures. Population figures are ONS mid-year population estimates 2020.
A7: Short-term detention orders are those of no greater than 24 hours' duration, except where a doctor has approved a further 12 hour extension. Prior to December 2017, the time limit for these orders was 72 hours. This data only includes those uses where the Place of Safety was a hospital. Orders made where the Place of Safety was a police station are reported separately by the Home Office.
B9: Number of Place of Safety Orders: Section 136 | C9: Base Population3 | D9: Crude rate per 100,000 population
A11: All1 | B11: tag_table2b_1
A13: All age groups (where recorded)2 | B13: tag_table2b_2
A15: 17 and under | B15: tag_table2b_3
A16: 15 and under
A17: 16 to 17
A19: 18 and over | B19: tag_table2b_4
A20: 18 to 34
A21: 35 to 49
A22: 50 to 64
A23: 65 and over
A25: All genders (where recorded)2 | B25: tag_table2b_5
A26: Male
A27: Female
A28: Non-Binary - based on Gender identity field
A29: Other (not listed) - based on Gender identity field
A30: Indeterminate - based on Person stated gender field
A33: Sources: MHSDS, ECDS 2021-22 - NHS Digital
A35: Footnotes 1) The total for 'All' is calculated from both the MHSDS and ECDS collections. It includes section 136 orders where the age and gender details were not submitted. 2) The totals for 'All age groups' and 'All genders' are from MHSDS only since the ECDS collection does not allow for further demographic breakdowns.These totals are lower than for 'All' as these also exclude records where these characteristics were either recorded as 'Not stated' and 'Not known' or where they were not submitted. 3) ONS mid-year population estimates 2020.
A37: Copyright © 2021, Health and Social Care Information Centre. The Health and Social Care Information Centre is a non-departmental body created by statute, also known as NHS Digital
A38: This work remains the sole and exclusive property of the Health and Social Information Centre and may only be reproduced where there is explicit reference to the ownership of the Health and Social Care Information Centre.

Sheet Table 2c
A1: Table 2c
A3: Uses of Short Term Detention Orders (Place of Safety Orders: Section 136) under the Mental Health Act 1983 by ethnicity 2021-22
A5: This table shows counts and rates of uses of section 136 by ethnicity, in 2021-22. Data about uses of Section 136 are incomplete in 2021-22 so the counts and rates shown are lower than the true figures. Population figures are from the 2011 Census as ONS mid-year estimates do not include updates for ethnicity.
A6: Short-term detention orders are defined as those of no greater than 24 hours' duration, except where a doctor has approved a further 12 hour extension. Prior to December 2017, the time limit for these orders was 72 hours.
A7: This data only includes those uses where the Place of Safety was a hospital. Orders made where the Place of Safety was a police station are reported separately by the Home Office.
A8: The population figures use 2011 Census categories. The 2011 Census introduced the new Gypsy or Irish Traveller and Arab categories. MHSDS does not allow for data to be submitted with these new categories and as such for the purpose of analysis the new Gypsy or Irish Traveller and Arab categories have not been included. The population figure for Gypsy or Irish Traveller is included in the total population figures for the broad category of White and the population figure for Arab is included in the population figures for Any Other Ethnic Group category. The inclusion of these groups could affect the rate for the Any other ethnic group. Although Gypsy and Arab are identified in the population figures, since these groups are not separately identified in the MHSDS, we cannot produce separate rates for these groups. We also do not know which categories these people would have identified as belonging to in the MHSDS. For example, an Arab person may have self-identified as Asian or Any Other Ethnic group and the way this affects the rates shown is unknown. The broad groupings shown below follow the 2001 Census groupings, which are still used in the NHS. However the 2011 census re-positions 'Chinese' from Any other ethnic group to Asian/Asian British. This means that figures using 2011 Census categories will not be comparable with any using 2001 Census categories for 'Any Other Ethnic Group' and 'Asian/Asian British'.
B10: Number of Place of Safety Orders: Section 136 | C10: Base Population3 | D10: Crude rate per 100,000 population | E10: Standardised rate per 100,000 population | F10: Confidence Interval
A12: All1 | B12: tag_table2c_1
A14: All ethnicities (where recorded)2 | B14: tag_table2c_2
A16: Ethnicity
A17: White | B17: tag_table2c_3
A18: White British
A19: White Irish
A20: Any Other White Background
A21: Gypsy or Irish Traveller
A23: Mixed | B23: tag_table2c_4
A24: White and Black Caribbean
A25: White and Black African
A26: White and Asian
A27: Any Other Mixed Background
A29: Asian or Asian British | B29: tag_table2c_5
A30: Indian
A31: Pakistani
A32: Bangladeshi
A33: Any Other Asian Background
A35: Black or Black British | B35: tag_table2c_6
A36: African
A37: Caribbean
A38: Any Other Black Background
A40: Other Ethnic Groups | B40: tag_table2c_7
A41: Chinese
A42: Any Other Ethnic Group
A43: Arab
A46: Sources: MHSDS, ECDS 2021-22 - NHS Digital
A48: Footnotes 1) The total for 'All' is calculated from both the MHSDS and ECDS collections. It includes detentions where the age and gender details were not submitted. Further breakdowns are from MHSDS only since the ECDS collection does not allow for further demographic breakdowns. 2) The total for 'All ethnicities' is lower than for 'All' as it excludes records where any of age, gender or ethnicity was either recorded as 'Not stated' and 'Not known' or where it was not submitted. This information was required for direct standardisation of population-based rates. 3) ONS Census 2011 - table reference: DC2101EW - Ethnic group by sex by age, QS211EW - Ethnic group (detailed)
A49: https://www.nomisweb.co.uk/census/2011/LC2101EW/view/2092957699?rows=c_ethpuk11&cols=c_sex
A51: Copyright © 2021, Health and Social Care Information Centre. The Health and Social Care Information Centre is a non-departmental body created by statute, also known as NHS Digital
A52: This work remains the sole and exclusive property of the Health and Social Information Centre and may only be reproduced where there is explicit reference to the ownership of the Health and Social Care Information Centre.

Sheet Table 3a
A1: Table 3a
A3: Uses of Community Treatment Orders (CTOs) by provider type, 2013-14 to 2021-22
A5: This table shows the number of uses of Community Treatment Orders (CTOs) during each period.
A6: Although a change in legal status from 'Informal to CTO' or 'Other sections to CTO' should not be possible, analysis of the MHSDS data shows that these transitions are being observed in the data submitted. This is shown below to highlight possible data quality issues. Data about uses of CTOs are incomplete in the MHSDS and should not be compared to data from the KP90 data source.
B8: All providers | L8: NHS Providers | V8: Independent Sector Providers
B9: 2013-14 | C9: 2014-15 | D9: 2015-16 | E9: 2016-17 | F9: 2017-18 | G9: 2018-19 | H9: 2019-20 | I9: 2020-21 | J9: 2021-22 | L9: 2013-14 | M9: 2014-15 | N9: 2015-16 | O9: 2016-17 | P9: 2017-18 | Q9: 2018-19 | R9: 2019-20 | S9: 2020-21 | T9: 2021-22 | V9: 2013-14 | W9: 2014-15 | X9: 2015-16 | Y9: 2016-17 | Z9: 2017-18 | AA9: 2018-19 | AB9: 2019-20 | AC9: 2020-21 | AD9: 2021-22
A11: Data source | B11: KP90 | C11: KP90 | D11: KP90 | E11: MHSDS1 | F11: MHSDS1 | G11: MHSDS1 | H11: MHSDS1 | I11: MHSDS1 | J11: MHSDS1 | L11: KP90 | M11: KP90 | N11: KP90 | O11: MHSDS1 | P11: MHSDS1 | Q11: MHSDS1 | R11: MHSDS1 | S11: MHSDS1 | T11: MHSDS1 | V11: KP90 | W11: KP90 | X11: KP90 | Y11: MHSDS | Z11: MHSDS | AA11: MHSDS | AB11: MHSDS | AC11: MHSDS | AD11: MHSDS
A13: Uses of Community Treatment Orders (under section 17A) | B13: 4434 | C13: 4564 | D13: 4361 | E13: 4966 | F13: 4784 | G13: 4840 | H13: 4650 | I13: 6070 | J13: tag_table3a_1 | L13: 4216 | M13: 4350 | N13: 4129 | O13: 4882 | P13: 4714 | Q13: 4768 | R13: 4601 | S13: 5986 | T13: tag_table3a_5 | V13: 218 | W13: 214 | X13: 232 | Y13: 84 | Z13: 70 | AA13: 72 | AB13: 49 | AC13: 84 | AD13: tag_table3a_9
A14: Section 3 to CTO | B14: 4099 | C14: 4323 | D14: 4109 | E14: 2645 | F14: 2693 | G14: 2675 | H14: 2790 | I14: 3517 | L14: 3906 | M14: 4128 | N14: 3905 | O14: 2602 | P14: 2661 | Q14: 2629 | R14: 2767 | S14: 3463 | V14: 193 | W14: 195 | X14: 204 | Y14: 43 | Z14: 32 | AA14: 46 | AB14: 23 | AC14: 54
A15: Section 37 to CTO | B15: 176 | C15: 178 | D15: 171 | E15: 113 | F15: 123 | G15: 144 | H15: 107 | I15: 115 | L15: 153 | M15: 162 | N15: 145 | O15: 108 | P15: 122 | Q15: 142 | R15: 103 | S15: 110 | V15: 23 | W15: 16 | X15: 26 | Y15: 5 | Z15: 1 | AA15: 2 | AB15: 4 | AC15: 5
A16: Section 47 to CTO | B16: 8 | C16: 6 | D16: 8 | E16: 4 | F16: 7 | G16: 5 | H16: 7 | I16: 14 | L16: 8 | M16: 4 | N16: 6 | O16: 4 | P16: 7 | Q16: 5 | R16: 6 | S16: 13 | V16: - | W16: 2 | X16: 2 | Y16: 0 | Z16: 0 | AA16: 0 | AB16: 1 | AC16: 1
A17: Section 48 to CTO | B17: - | C17: 1 | D17: 2 | E17: 62 | F17: 55 | G17: 2 | H17: 2 | I17: 8 | L17: - | M17: 1 | N17: 2 | O17: 62 | P17: 55 | Q17: 2 | R17: 2 | S17: 8 | V17: - | W17: - | X17: - | Y17: 0 | Z17: 0 | AA17: 0 | AB17: 0 | AC17: 0
A18: Informal to CTO2 | B18: - | C18: - | D18: - | E18: 1374 | F18: 1060 | G18: 1189 | H18: 997 | I18: 1093 | L18: - | M18: - | N18: - | O18: 1351 | P18: 1048 | Q18: 1185 | R18: 997 | S18: 1091 | V18: - | W18: - | X18: - | Y18: 23 | Z18: 12 | AA18: 4 | AB18: 0 | AC18: 2
A19: Other sections to CTO3 | B19: 151 | C19: 56 | D19: 71 | E19: 768 | F19: 846 | G19: 825 | H19: 747 | I19: 1323 | L19: 149 | M19: 55 | N19: 71 | O19: 755 | P19: 821 | Q19: 805 | R19: 726 | S19: 1301 | V19: 2 | W19: 1 | X19: - | Y19: 13 | Z19: 25 | AA19: 20 | AB19: 21 | AC19: 22
A21: CTO recalls to hospital | B21: 2316 | C21: 2369 | D21: 2294 | E21: 500 | F21: 519 | G21: 482 | H21: 514 | I21: 621 | J21: tag_table3a_2 | L21: 2239 | M21: 2303 | N21: 2240 | O21: 483 | P21: 514 | Q21: 476 | R21: 505 | S21: 614 | T21: tag_table3a_6 | V21: 77 | W21: 66 | X21: 54 | Y21: 17 | Z21: 5 | AA21: 6 | AB21: 9 | AC21: 7 | AD21: tag_table3a_10
A23: Revocations of CTO4 | B23: 1401 | C23: 1427 | D23: 1557 | E23: 524 | F23: 444 | G23: 437 | H23: 434 | I23: 555 | J23: tag_table3a_3 | L23: 1349 | M23: 1376 | N23: 1518 | O23: 514 | P23: 441 | Q23: 430 | R23: 428 | S23: 545 | T23: tag_table3a_7 | V23: 52 | W23: 51 | X23: 39 | Y23: 10 | Z23: 3 | AA23: 7 | AB23: 6 | AC23: 10 | AD23: tag_table3a_11
